<?xml version="1.0"?>
<robot name="drone" xmlns:xacro="http://ros.org/wiki/xacro">

     <material name="White">
            <color rgba="1 1 1 1" />
     </material>


     <material name="Black">
            <color rgba="0 0 0 1" />
     </material>

     <material name="Orange">
            <color rgba="1 0.5 0 1" />
     </material>

     <material name="Green">
            <color rgba="0 1 0 1" />
     </material>

     <material name="Grey">
            <color rgba="0.5 0.5 0.5 1" />
     </material>


     <!-- virtual link -->
     <link name="base_footprint">
     </link>
     <link name="base_link">
        <visual>
            <geometry>
                <box size="0.3 0.3 0.1" />
            </geometry>
            <origin xyz="0 0 0.05" rpy ="0 0 0" />
            <material name="Grey" />
        </visual>
        <collision>
            <geometry>
                <box size="0.5 0.3 0.1" />
            </geometry>
            <!-- 0.7854 -->
            <origin xyz="0 0 0" rpy="0 0 0" />
        </collision>
        <inertial>
           <mass value="1.0" />
           <origin xyz="0 0 0" rpy="0 0 0" />
           <inertia ixx="0.0025" ixy="0.0" ixz="0.0" iyy="0.0025" iyz="0.0" izz="0.0025"/>
        </inertial>
     </link>


     <!-- virtual joint -->
     <joint name="base_joint" type="fixed">
        <parent link ="base_footprint" />
        <child link ="base_link" />
     </joint>

     <!-- arm1 -->
     <link name="arm1">
         <visual>
            <geometry>
                 <cylinder length="0.2" radius="0.02" />
            </geometry>
            <origin xyz="0.071 0.071 0" rpy="-0.7854 1.57 0" />
            <material name="Orange" />
         </visual>
         <collision>
            <geometry>
                 <cylinder length="0.4" radius="0.02" />
            </geometry>
            <origin xyz="0.071 0.071 0" rpy="-0.7854  1.57 0" />
         </collision>
         <inertial>
            <mass value="0.1" />
            <inertia ixx="0.0001" ixy="0.0" ixz="0.0" iyy="0.0001" iyz="0.0" izz="0.0001" />
            <origin xyz="0 0 0" rpy="0 0 0" />
         </inertial>
     </link>

          <!-- arm2 -->
     <link name="arm2">
         <visual>
            <geometry>
                 <cylinder length="0.2" radius="0.02" />
            </geometry>
            <origin xyz="-0.071 0.071 0" rpy="0.7854 1.57 0" />
            <material name="Orange" />
         </visual>
         <collision>
            <geometry>
                 <cylinder length="0.4" radius="0.02" />
            </geometry>
            <origin xyz="0.071 0.071 0" rpy="0.7854 1.57 0" />
         </collision>
         <inertial>
            <mass value="0.1" />
            <inertia ixx="0.0001" ixy="0.0" ixz="0.0" iyy="0.0001" iyz="0.0" izz="0.0001" />
            <origin xyz="0 0 0" rpy="0 0 0" />
         </inertial>
     </link>


          <!-- arm3 -->
     <link name="arm3">
         <visual>
            <geometry>
                 <cylinder length="0.2" radius="0.02" />
            </geometry>
            <origin xyz="0.071 -0.071 0" rpy="-0.7854 -1.57 0" />
            <material name="Orange" />
         </visual>
         <collision>
            <geometry>
                 <cylinder length="0.4" radius="0.02" />
            </geometry>
            <origin xyz="-0.071 -0.071 0" rpy="-0.7854 -1.57 0" />
         </collision>
         <inertial>
            <mass value="0.1" />
            <inertia ixx="0.0001" ixy="0.0" ixz="0.0" iyy="0.0001" iyz="0.0" izz="0.0001" />
            <origin xyz="0 0 0" rpy="0 0 0" />
         </inertial>
     </link>
  

          <!-- arm4 -->
     <link name="arm4">
         <visual>
            <geometry>
                 <cylinder length="0.2" radius="0.02" />
            </geometry>
            <origin xyz="-0.071 -0.071 0" rpy="-0.7854 1.57 0" />
            <material name="Orange" />
         </visual>
         <collision>
            <geometry>
                 <cylinder length="0.4" radius="0.02" />
            </geometry>
            <origin xyz="0.095 0.095 0" rpy="-0.7854 1.57 0" />
         </collision>
         <inertial>
            <mass value="0.1" />
            <inertia ixx="0.0001" ixy="0.0" ixz="0.0" iyy="0.0001" iyz="0.0" izz="0.0001"/>
            <origin xyz="0 0 0" rpy="0 0 0" />
         </inertial>
     </link>

    

     <!-- motors -->
     <link name="motor1">
         <visual>
            <geometry>
                 <cylinder length="0.1" radius="0.03" />
            </geometry>
            <origin xyz="0 0 0" rpy="0 0 0" />
            <material name="Grey" />
         </visual>
         <collision>
            <geometry>
                 <cylinder length="0.1" radius="0.03" />
            </geometry>
            <origin xyz="0 0 0" rpy="0 0 0" />
         </collision>
         <inertial>
            <mass value="0.05" />
            <inertia ixx="0.00001" ixy="0.0" ixz="0.0" iyy="0.00001" iyz="0.0" izz="0.00001" />
            <origin xyz="0 0 0" rpy="0 0 0" />
         </inertial>
     </link>

     <link name="motor2">
         <visual>
            <geometry>
                 <cylinder length="0.1" radius="0.03" />
            </geometry>
            <origin xyz="0 0 0" rpy="0 0 0" />
            <material name="Grey" />
         </visual>
         <collision>
            <geometry>
                 <cylinder length="0.1" radius="0.03" />
            </geometry>
            <origin xyz="0 0 0" rpy="0 0 0" />
         </collision>
         <inertial>
            <mass value="0.05" />
            <inertia ixx="0.00001" ixy="0.0" ixz="0.0" iyy="0.00001" iyz="0.0" izz="0.00001" />
            <origin xyz="0 0 0" rpy="0 0 0" />
         </inertial>
     </link>

     <link name="motor3">
         <visual>
            <geometry>
                 <cylinder length="0.1" radius="0.03" />
            </geometry>
            <origin xyz="0 0 0" rpy="0 0 0" />
            <material name="Grey" />
         </visual>
         <collision>
            <geometry>
                 <cylinder length="0.1" radius="0.03" />
            </geometry>
            <origin xyz="0 0 0" rpy="0 0 0" />
         </collision>
         <inertial>
            <mass value="0.05" />
            <inertia ixx="0.00001" ixy="0.0" ixz="0.0" iyy="0.00001" iyz="0.0" izz="0.00001" />
            <origin xyz="0 0 0" rpy="0 0 0" />
         </inertial>
     </link>

     <link name="motor4">
         <visual>
            <geometry>
                 <cylinder length="0.1" radius="0.03" />
            </geometry>
            <origin xyz="0 0 0" rpy="0 0 0" />
            <material name="Grey" />
         </visual>
         <collision>
            <geometry>
                 <cylinder length="0.1" radius="0.03" />
            </geometry>
            <origin xyz="0 0 0" rpy="0 0 0" />
         </collision>
         <inertial>
            <mass value="0.05" />
            <inertia ixx="0.00001" ixy="0.0" ixz="0.0" iyy="0.00001" iyz="0.0" izz="0.00001" />
            <origin xyz="0 0 0" rpy="0 0 0" />
         </inertial>
     </link>

 
     <!-- propellers -->
     <link name="p1">
         <visual>
            <geometry>
                 <cylinder length="0.01" radius="0.05" />
            </geometry>
            <origin xyz="0 0 0" rpy="0 0 0" />
            <material name="Grey" />
         </visual>
         <collision>
            <geometry>
                 <cylinder length="0.01" radius="0.05" />
            </geometry>
            <origin xyz="0 0 0" rpy="0 0 0" />
         </collision>
         <inertial>
            <mass value="0.05" />
            <inertia ixx="0.00001" ixy="0.0" ixz="0.0" iyy="0.00001" iyz="0.0" izz="0.00001" />
            <origin xyz="0 0 0" rpy="0 0 0" />
         </inertial>
     </link>

     <link name="p2">
         <visual>
            <geometry>
                 <cylinder length="0.01" radius="0.05" />
            </geometry>
            <origin xyz="0 0 0" rpy="0 0 0" />
            <material name="Grey" />
         </visual>
         <collision>
            <geometry>
                 <cylinder length="0.01" radius="0.05" />
            </geometry>
            <origin xyz="0 0 0" rpy="0 0 0" />
         </collision>
         <inertial>
            <mass value="0.05" />
            <inertia ixx="0.00001" ixy="0.0" ixz="0.0" iyy="0.00001" iyz="0.0" izz="0.00001" />
            <origin xyz="0 0 0" rpy="0 0 0" />
         </inertial>
     </link>

     <link name="p3">
         <visual>
            <geometry>
                 <cylinder length="0.01" radius="0.05" />
            </geometry>
            <origin xyz="0 0 0" rpy="0 0 0" />
            <material name="Grey" />
         </visual>
         <collision>
            <geometry>
                 <cylinder length="0.01" radius="0.05" />
            </geometry>
            <origin xyz="0 0 0" rpy="0 0 0" />
         </collision>
         <inertial>
            <mass value="0.05" />
            <inertia ixx="0.00001" ixy="0.0" ixz="0.0" iyy="0.00001" iyz="0.0" izz="0.00001" />
            <origin xyz="0 0 0" rpy="0 0 0" />
         </inertial>
     </link>

     <link name="p4">
         <visual>
            <geometry>
                 <cylinder length="0.01" radius="0.05" />
            </geometry>
            <origin xyz="0 0 0" rpy="0 0 0" />
            <material name="Grey" />
         </visual>
         <collision>
            <geometry>
                 <cylinder length="0.1" radius="0.03" />
            </geometry>
            <origin xyz="0 0 0" rpy="0 0 0" />
         </collision>
         <inertial>
            <mass value="0.01" />
            <inertia ixx="0.00001" ixy="0.0" ixz="0.0" iyy="0.00001" iyz="0.0" izz="0.00001" />
            <origin xyz="0 0 0" rpy="0 0 0" />
         </inertial>
     </link>     


     <!-- joints -->
     <joint name="joint_1" type="fixed" >
          <parent link ="base_link" />
          <child link="arm1" />
          <origin xyz="0.1 0.1 0.04" rpy="0 0 0" />
     </joint>

     <joint name="joint_2" type="fixed" >
          <parent link ="base_link" />
          <child link="arm2" />
          <origin xyz="-0.1 0.1 0.04" rpy="0 0 0" />
     </joint>

     <joint name="joint_3" type="fixed" >
          <parent link ="base_link" />
          <child link="arm3" />
          <origin xyz="0.1 -0.1 0.04" rpy="0 0 0" />
     </joint>

     <joint name="joint_4" type="fixed" >
          <parent link ="base_link" />
          <child link="arm4" />
          <origin xyz="-0.1 -0.1 0.04" rpy="0 0 0" />
     </joint>

     <joint name="joint_m1" type="fixed" >
          <parent link ="arm1" />
          <child link="motor1" />
          <axis xyz="0 0 0" rpy="0 0 0" />
          <origin xyz="0.145 0.145 0.05" rpy="0 0 0" />
     </joint>

     <joint name="joint_m2" type="fixed" >
          <parent link ="arm2" />
          <child link="motor2" />
          <axis xyz="0 0 0" rpy="0 0 0" />
          <origin xyz="-0.145 0.145 0.05" rpy="0 0 0" />
     </joint>


     <joint name="joint_m3" type="fixed" >
          <parent link ="arm3" />
          <child link="motor3" />
          <axis xyz="0 0 0" rpy="0 0 0" />
          <origin xyz="0.145 -0.145  0.05" rpy="0 0 0" />
     </joint>

     <joint name="joint_m4" type="fixed">
          <parent link ="arm4" />
          <child link="motor4" />
          <axis xyz="0 0 0" rpy="0 0 0" />
          <origin xyz="-0.145 -0.145 0.05" rpy="0 0 0" />
     </joint>
  
     <joint name="joint_p1" type="continuous">
          <parent link ="motor1" />
          <child link="p1" />
          <origin xyz="0 0 0.05" rpy="0 0 0" />
          <axis xyz="0 0 1" rpy="0 0 0" />
     </joint>

     <joint name="joint_p2" type="continuous">
          <parent link ="motor2" />
          <child link="p2" />
          <origin xyz="0 0 0.05" rpy="0 0 0" />
          <axis xyz="0 0 1" rpy="0 0 0" />
     </joint>

     <joint name="joint_p3" type="continuous">
          <parent link ="motor3" />
          <child link="p3" />
          <origin xyz="0 0 0.05" rpy="0 0 0" />
          <axis xyz="0 0 1" rpy="0 0 0" />
     </joint>

     <joint name="joint_p4" type="continuous">
          <parent link ="motor4" />
          <child link="p4" />
          <origin xyz="0 0 0.05" rpy="0 0 0" />
          <axis xyz="0 0 1" rpy="0 0 0" />
     </joint>

<!-- we can use <material name="" color rbga="0 0 0 1" /> for color -->
     <gazebo reference ="base_link" >
         <mu1>0.2</mu1>
         <mu2>0.2</mu2>
         <material>Gazebo/Grey</material>
     </gazebo>

     <gazebo reference ="arm1" >
         <mu1>0.2</mu1>
         <mu2>0.2</mu2>
         <material>Gazebo/Orange</material>
     </gazebo>

     <gazebo reference ="arm2" >
         <mu1>0.2</mu1>
         <mu2>0.2</mu2>
         <material>Gazebo/Orange</material>
     </gazebo>

     <gazebo reference ="arm3" >
         <mu1>0.2</mu1>
         <mu2>0.2</mu2>
         <material>Gazebo/Orange</material>
     </gazebo>

     <gazebo reference ="arm4" >
         <mu1>0.2</mu1>
         <mu2>0.2</mu2>
         <material>Gazebo/Orange</material>
     </gazebo>


     <gazebo reference ="motor1" >
         <mu1>0.2</mu1>
         <mu2>0.2</mu2>
         <material>Gazebo/Grey</material>
     </gazebo>

     <gazebo reference ="motor2" >
         <mu1>0.2</mu1>
         <mu2>0.2</mu2>
         <material>Gazebo/Grey</material>
     </gazebo>

     <gazebo reference ="motor3" >
         <mu1>0.2</mu1>
         <mu2>0.2</mu2>
         <material>Gazebo/Grey</material>
     </gazebo>

     <gazebo reference ="motor4" >
         <mu1>0.2</mu1>
         <mu2>0.2</mu2>
         <material>Gazebo/Grey</material>
     </gazebo> 
 
     <gazebo reference ="p1" >
            <mu1>0.2</mu1>
            <mu2>0.2</mu2>
            <material>Gazebo/Grey</material>
     </gazebo>

     <gazebo reference ="p2" >
            <mu1>0.2</mu1>
            <mu2>0.2</mu2>
            <material>Gazebo/Grey</material>
     </gazebo>

     <gazebo reference ="p3" >
            <mu1>0.2</mu1>
            <mu2>0.2</mu2>
            <material>Gazebo/Grey</material>
     </gazebo>

     <gazebo reference ="p4" >
            <mu1>0.2</mu1>
            <mu2>0.2</mu2>
            <material>Gazebo/Grey</material>
     </gazebo>

</robot>
